2023-11-15 22:41:36,207 ERROR: Exception on /edit_profile [POST] [in /Volumes/data/devtech/projects/pythonProject/microblog/venv/lib/python3.12/site-packages/flask/app.py:825]
Traceback (most recent call last):
  File "/Volumes/data/devtech/projects/pythonProject/microblog/venv/lib/python3.12/site-packages/sqlalchemy/engine/base.py", line 1969, in _exec_single_context
    self.dialect.do_execute(
  File "/Volumes/data/devtech/projects/pythonProject/microblog/venv/lib/python3.12/site-packages/sqlalchemy/engine/default.py", line 922, in do_execute
    cursor.execute(statement, parameters)
sqlite3.IntegrityError: UNIQUE constraint failed: user.username

The above exception was the direct cause of the following exception:

Traceback (most recent call last):
  File "/Volumes/data/devtech/projects/pythonProject/microblog/venv/lib/python3.12/site-packages/flask/app.py", line 1455, in wsgi_app
    response = self.full_dispatch_request()
               ^^^^^^^^^^^^^^^^^^^^^^^^^^^^
  File "/Volumes/data/devtech/projects/pythonProject/microblog/venv/lib/python3.12/site-packages/flask/app.py", line 869, in full_dispatch_request
    rv = self.handle_user_exception(e)
         ^^^^^^^^^^^^^^^^^^^^^^^^^^^^^
  File "/Volumes/data/devtech/projects/pythonProject/microblog/venv/lib/python3.12/site-packages/flask/app.py", line 867, in full_dispatch_request
    rv = self.dispatch_request()
         ^^^^^^^^^^^^^^^^^^^^^^^
  File "/Volumes/data/devtech/projects/pythonProject/microblog/venv/lib/python3.12/site-packages/flask/app.py", line 852, in dispatch_request
    return self.ensure_sync(self.view_functions[rule.endpoint])(**view_args)
           ^^^^^^^^^^^^^^^^^^^^^^^^^^^^^^^^^^^^^^^^^^^^^^^^^^^^^^^^^^^^^^^^^
  File "/Volumes/data/devtech/projects/pythonProject/microblog/app/routes.py", line 95, in edit_profile
    db.session.commit()
  File "/Volumes/data/devtech/projects/pythonProject/microblog/venv/lib/python3.12/site-packages/sqlalchemy/orm/scoping.py", line 597, in commit
    return self._proxied.commit()
           ^^^^^^^^^^^^^^^^^^^^^^
  File "/Volumes/data/devtech/projects/pythonProject/microblog/venv/lib/python3.12/site-packages/sqlalchemy/orm/session.py", line 1967, in commit
    trans.commit(_to_root=True)
  File "<string>", line 2, in commit
  File "/Volumes/data/devtech/projects/pythonProject/microblog/venv/lib/python3.12/site-packages/sqlalchemy/orm/state_changes.py", line 139, in _go
    ret_value = fn(self, *arg, **kw)
                ^^^^^^^^^^^^^^^^^^^^
  File "/Volumes/data/devtech/projects/pythonProject/microblog/venv/lib/python3.12/site-packages/sqlalchemy/orm/session.py", line 1256, in commit
    self._prepare_impl()
  File "<string>", line 2, in _prepare_impl
  File "/Volumes/data/devtech/projects/pythonProject/microblog/venv/lib/python3.12/site-packages/sqlalchemy/orm/state_changes.py", line 139, in _go
    ret_value = fn(self, *arg, **kw)
                ^^^^^^^^^^^^^^^^^^^^
  File "/Volumes/data/devtech/projects/pythonProject/microblog/venv/lib/python3.12/site-packages/sqlalchemy/orm/session.py", line 1231, in _prepare_impl
    self.session.flush()
  File "/Volumes/data/devtech/projects/pythonProject/microblog/venv/lib/python3.12/site-packages/sqlalchemy/orm/session.py", line 4310, in flush
    self._flush(objects)
  File "/Volumes/data/devtech/projects/pythonProject/microblog/venv/lib/python3.12/site-packages/sqlalchemy/orm/session.py", line 4445, in _flush
    with util.safe_reraise():
  File "/Volumes/data/devtech/projects/pythonProject/microblog/venv/lib/python3.12/site-packages/sqlalchemy/util/langhelpers.py", line 146, in __exit__
    raise exc_value.with_traceback(exc_tb)
  File "/Volumes/data/devtech/projects/pythonProject/microblog/venv/lib/python3.12/site-packages/sqlalchemy/orm/session.py", line 4406, in _flush
    flush_context.execute()
  File "/Volumes/data/devtech/projects/pythonProject/microblog/venv/lib/python3.12/site-packages/sqlalchemy/orm/unitofwork.py", line 466, in execute
    rec.execute(self)
  File "/Volumes/data/devtech/projects/pythonProject/microblog/venv/lib/python3.12/site-packages/sqlalchemy/orm/unitofwork.py", line 642, in execute
    util.preloaded.orm_persistence.save_obj(
  File "/Volumes/data/devtech/projects/pythonProject/microblog/venv/lib/python3.12/site-packages/sqlalchemy/orm/persistence.py", line 85, in save_obj
    _emit_update_statements(
  File "/Volumes/data/devtech/projects/pythonProject/microblog/venv/lib/python3.12/site-packages/sqlalchemy/orm/persistence.py", line 909, in _emit_update_statements
    c = connection.execute(
        ^^^^^^^^^^^^^^^^^^^
  File "/Volumes/data/devtech/projects/pythonProject/microblog/venv/lib/python3.12/site-packages/sqlalchemy/engine/base.py", line 1416, in execute
    return meth(
           ^^^^^
  File "/Volumes/data/devtech/projects/pythonProject/microblog/venv/lib/python3.12/site-packages/sqlalchemy/sql/elements.py", line 516, in _execute_on_connection
    return connection._execute_clauseelement(
           ^^^^^^^^^^^^^^^^^^^^^^^^^^^^^^^^^^
  File "/Volumes/data/devtech/projects/pythonProject/microblog/venv/lib/python3.12/site-packages/sqlalchemy/engine/base.py", line 1639, in _execute_clauseelement
    ret = self._execute_context(
          ^^^^^^^^^^^^^^^^^^^^^^
  File "/Volumes/data/devtech/projects/pythonProject/microblog/venv/lib/python3.12/site-packages/sqlalchemy/engine/base.py", line 1848, in _execute_context
    return self._exec_single_context(
           ^^^^^^^^^^^^^^^^^^^^^^^^^^
  File "/Volumes/data/devtech/projects/pythonProject/microblog/venv/lib/python3.12/site-packages/sqlalchemy/engine/base.py", line 1988, in _exec_single_context
    self._handle_dbapi_exception(
  File "/Volumes/data/devtech/projects/pythonProject/microblog/venv/lib/python3.12/site-packages/sqlalchemy/engine/base.py", line 2343, in _handle_dbapi_exception
    raise sqlalchemy_exception.with_traceback(exc_info[2]) from e
  File "/Volumes/data/devtech/projects/pythonProject/microblog/venv/lib/python3.12/site-packages/sqlalchemy/engine/base.py", line 1969, in _exec_single_context
    self.dialect.do_execute(
  File "/Volumes/data/devtech/projects/pythonProject/microblog/venv/lib/python3.12/site-packages/sqlalchemy/engine/default.py", line 922, in do_execute
    cursor.execute(statement, parameters)
sqlalchemy.exc.IntegrityError: (sqlite3.IntegrityError) UNIQUE constraint failed: user.username
[SQL: UPDATE user SET username=?, about_me=? WHERE user.id = ?]
[parameters: ('susi', 'This is my new profile page which is working fine now. Whats up? :)!', 3)]
(Background on this error at: https://sqlalche.me/e/20/gkpj)
2023-11-16 22:45:50,398 INFO: Raj's Blog startup [in /Volumes/data/devtech/projects/pythonProject/microblog/app/__init__.py:42]
2023-11-16 22:46:03,632 ERROR: Exception on /edit_profile [POST] [in /Volumes/data/devtech/projects/pythonProject/microblog/venv/lib/python3.12/site-packages/flask/app.py:825]
Traceback (most recent call last):
  File "/Volumes/data/devtech/projects/pythonProject/microblog/venv/lib/python3.12/site-packages/flask/app.py", line 1455, in wsgi_app
    response = self.full_dispatch_request()
               ^^^^^^^^^^^^^^^^^^^^^^^^^^^^
  File "/Volumes/data/devtech/projects/pythonProject/microblog/venv/lib/python3.12/site-packages/flask/app.py", line 869, in full_dispatch_request
    rv = self.handle_user_exception(e)
         ^^^^^^^^^^^^^^^^^^^^^^^^^^^^^
  File "/Volumes/data/devtech/projects/pythonProject/microblog/venv/lib/python3.12/site-packages/flask/app.py", line 867, in full_dispatch_request
    rv = self.dispatch_request()
         ^^^^^^^^^^^^^^^^^^^^^^^
  File "/Volumes/data/devtech/projects/pythonProject/microblog/venv/lib/python3.12/site-packages/flask/app.py", line 852, in dispatch_request
    return self.ensure_sync(self.view_functions[rule.endpoint])(**view_args)
           ^^^^^^^^^^^^^^^^^^^^^^^^^^^^^^^^^^^^^^^^^^^^^^^^^^^^^^^^^^^^^^^^^
  File "/Volumes/data/devtech/projects/pythonProject/microblog/venv/lib/python3.12/site-packages/flask_login/utils.py", line 290, in decorated_view
    return current_app.ensure_sync(func)(*args, **kwargs)
           ^^^^^^^^^^^^^^^^^^^^^^^^^^^^^^^^^^^^^^^^^^^^^^
  File "/Volumes/data/devtech/projects/pythonProject/microblog/app/routes.py", line 93, in edit_profile
    if form.validate_on_submit():
       ^^^^^^^^^^^^^^^^^^^^^^^^^
  File "/Volumes/data/devtech/projects/pythonProject/microblog/venv/lib/python3.12/site-packages/flask_wtf/form.py", line 86, in validate_on_submit
    return self.is_submitted() and self.validate(extra_validators=extra_validators)
                                   ^^^^^^^^^^^^^^^^^^^^^^^^^^^^^^^^^^^^^^^^^^^^^^^^
  File "/Volumes/data/devtech/projects/pythonProject/microblog/venv/lib/python3.12/site-packages/wtforms/form.py", line 329, in validate
    return super().validate(extra)
           ^^^^^^^^^^^^^^^^^^^^^^^
  File "/Volumes/data/devtech/projects/pythonProject/microblog/venv/lib/python3.12/site-packages/wtforms/form.py", line 146, in validate
    if not field.validate(self, extra):
           ^^^^^^^^^^^^^^^^^^^^^^^^^^^
  File "/Volumes/data/devtech/projects/pythonProject/microblog/venv/lib/python3.12/site-packages/wtforms/fields/core.py", line 246, in validate
    stop_validation = self._run_validation_chain(form, chain)
                      ^^^^^^^^^^^^^^^^^^^^^^^^^^^^^^^^^^^^^^^
  File "/Volumes/data/devtech/projects/pythonProject/microblog/venv/lib/python3.12/site-packages/wtforms/fields/core.py", line 266, in _run_validation_chain
    validator(form, self)
TypeError: EditProfileForm.validate_username() takes 1 positional argument but 2 were given
2023-11-16 22:48:25,187 INFO: Raj's Blog startup [in /Volumes/data/devtech/projects/pythonProject/microblog/app/__init__.py:42]
